Workbook

Sheet Population
A1: Population | B1: Austria | C1: Belgium | D1: Brazil | E1: Canada | F1: Denmark | G1: Finland | H1: France | I1: Germany | J1: Italy | K1: Japan | L1: Netherlands | M1: N. Zealand | N1: Norway | O1: Portugal | P1: Spain | Q1: Sri Lanka | R1: Sweden | S1: Switzerland | T1: UK | U1: USA | V1: Uruguay | X1: Austria | Y1: Belgium | Z1: Brazil | AA1: Canada | AB1: Denmark | AC1: Finland | AD1: France | AE1: Germany | AF1: Italy | AG1: Japan | AH1: Netherlands | AI1: N. Zealand | AJ1: Norway | AK1: Portugal | AL1: Spain | AM1: Sri Lanka | AN1: Sweden | AO1: Switzerland | AP1: UK | AQ1: USA | AR1: Uruguay | AS1: Growth Rate | AT1: Austria | AU1: Belgium | AV1: Brazil | AW1: Canada | AX1: Denmark | AY1: Finland | AZ1: France | BA1: Germany | BB1: Italy | BC1: Japan | BD1: Netherlands | BE1: N. Zealand | BF1: Norway | BG1: Portugal | BH1: Spain | BI1: Sri Lanka | BJ1: Sweden | BK1: Switzerland | BL1: UK | BM1: USA | BN1: Uruguay
A2: 1870 | B2: 4520 | C2: 5096 | D2: 9797 | E2: 3781 | F2: 1888 | G2: 1754 | H2: 38440 | I2: 39231 | J2: 27888 | K2: 34437 | L2: 3610 | M2: 291 | N2: 1735 | O2: 4327 | P2: 16201 | Q2: 2786 | R2: 4164 | S2: 2655 | T2: 31400 | U2: 40240.63 | V2: 343 | X2: =LN(B2) -> 8.4162673 | Y2: =LN(C2) -> 8.5362112 | Z2: =LN(D2) -> 9.1898315 | AA2: =LN(E2) -> 8.2377438 | AB2: =LN(F2) -> 7.5432733 | AC2: =LN(G2) -> 7.4696542 | AD2: =LN(H2) -> 10.556854 | AE2: =LN(I2) -> 10.577223 | ... AR2: =LN(V2) -> 5.8377304
A3: 1871 | B3: 4562 | C3: 5137 | D3: 9980 | E3: 3801 | F3: 1903 | G3: 1786 | H3: 37731 | I3: 39456 | J3: 28063 | K3: 34648 | L3: 3636 | M3: 306 | N3: 1745 | O3: 4353 | P3: 16258 | Q3: 2820 | R3: 4186 | S3: 2680 | T3: 31685 | U3: 41098 | V3: 354 | X3: =LN(B3) -> 8.4255164 | Y3: =LN(C3) -> 8.5442245 | Z3: =LN(D3) -> 9.2083384 | AA3: =LN(E3) -> 8.2430195 | AB3: =LN(F3) -> 7.5511869 | AC3: =LN(G3) -> 7.4877338 | AD3: =LN(H3) -> 10.538237 | AE3: =LN(I3) -> 10.582941 | ... AR3: =LN(V3) -> 5.8692969 | AT3: =X3-X2 -> 0.00924913 | AU3: =Y3-Y2 -> 0.0080133332 | AV3: =Z3-Z2 -> 0.018506874 | AW3: =AA3-AA2 -> 0.0052756651 | AX3: =AB3-AB2 -> 0.0079135206 | AY3: =AC3-AC2 -> 0.018079589 | AZ3: =AD3-AD2 -> -0.018616546 | BA3: =AE3-AE2 -> 0.0057188764 | ... BN3: =AR3-AR2 -> 0.031566466
A4: 1872 | B4: 4604 | C4: 5178 | D4: 10167 | E4: 3870 | F4: 1918 | G4: 1819 | H4: 37679 | I4: 39691 | J4: 28233 | K4: 34859 | L4: 3662 | M4: 320 | N4: 1755 | O4: 4379 | P4: 16315 | Q4: 2842 | R4: 4227 | S4: 2697 | T4: 31874 | U4: 42136 | V4: 364 | X4: =LN(B4) -> 8.4346808 | Y4: =LN(C4) -> 8.5521742 | Z4: =LN(D4) -> 9.2269025 | AA4: =LN(E4) -> 8.2610098 | AB4: =LN(F4) -> 7.5590383 | AC4: =LN(G4) -> 7.5060422 | AD4: =LN(H4) -> 10.536858 | AE4: =LN(I4) -> 10.58888 | ... AR4: =LN(V4) -> 5.8971539 | AT4: =X4-X3 -> 0.009164367 | AU4: =Y4-Y3 -> 0.0079496298 | AV4: =Z4-Z3 -> 0.018564091 | AW4: =AA4-AA3 -> 0.017990317 | AX4: =AB4-AB3 -> 0.0078513881 | AY4: =AC4-AC3 -> 0.018308417 | AZ4: =AD4-AD3 -> -0.0013791277 | BA4: =AE4-AE3 -> 0.0059383348 | ... BN4: =AR4-AR3 -> 0.027856955
A5: 1873 | B5: 4646 | C5: 5219 | D5: 10358 | E5: 3943 | F5: 1935 | G5: 1847 | H5: 37887 | I5: 40017 | J5: 28387 | K5: 35070 | L5: 3670 | M5: 335 | N5: 1767 | O5: 4405 | P5: 16372 | Q5: 2863 | R5: 4274 | S5: 2715 | T5: 32177 | U5: 43174 | V5: 376 | X5: =LN(B5) -> 8.4437619 | Y5: =LN(C5) -> 8.5600611 | Z5: =LN(D5) -> 9.2455144 | AA5: =LN(E5) -> 8.2796971 | AB5: =LN(F5) -> 7.5678626 | AC5: =LN(G5) -> 7.521318 | AD5: =LN(H5) -> 10.542363 | AE5: =LN(I5) -> 10.59706 | ... AR5: =LN(V5) -> 5.9295891 | AT5: =X5-X4 -> 0.0090811435 | AU5: =Y5-Y4 -> 0.0078869313 | AV5: =Z5-Z4 -> 0.018611987 | AW5: =AA5-AA4 -> 0.018687348 | AX5: =AB5-AB4 -> 0.00882435 | AY5: =AC5-AC4 -> 0.015275802 | AZ5: =AD5-AD4 -> 0.0055051353 | BA5: =AE5-AE4 -> 0.0081799021 | ... BN5: =AR5-AR4 -> 0.032435276
A6: 1874 | B6: 4688 | C6: 5261 | D6: 10552 | E6: 4012 | F6: 1954 | G6: 1873 | H6: 38044 | I6: 40450 | J6: 28505 | K6: 35235 | L6: 3745 | M6: 367 | N6: 1783 | O6: 4431 | P6: 16429 | Q6: 2885 | R6: 4320 | S6: 2733 | T6: 32501 | U6: 44212 | V6: 387 | X6: =LN(B6) -> 8.4527613 | Y6: =LN(C6) -> 8.5680764 | Z6: =LN(D6) -> 9.2640707 | AA6: =LN(E6) -> 8.2970451 | AB6: =LN(F6) -> 7.5776338 | AC6: =LN(G6) -> 7.5352967 | AD6: =LN(H6) -> 10.546499 | AE6: =LN(I6) -> 10.607822 | ... AR6: =LN(V6) -> 5.9584247 | AT6: =X6-X5 -> 0.0089994179 | AU6: =Y6-Y5 -> 0.0080153101 | AV6: =Z6-Z5 -> 0.018556247 | AW6: =AA6-AA5 -> 0.017348015 | AX6: =AB6-AB5 -> 0.0097712271 | AY6: =AC6-AC5 -> 0.013978722 | AZ6: =AD6-AD5 -> 0.0041353393 | BA6: =AE6-AE5 -> 0.01076228 | ... BN6: =AR6-AR5 -> 0.02883555
A7: 1875 | B7: 4730 | C7: 5303 | D7: 10749 | E7: 4071 | F7: 1973 | G7: 1899 | H7: 38221 | I7: 40897 | J7: 28630 | K7: 35436 | L7: 3788 | M7: 406 | N7: 1803 | O7: 4458 | P7: 16487 | Q7: 2908 | R7: 4362 | S7: 2750 | T7: 32839 | U7: 45245 | V7: 399 | X7: =LN(B7) -> 8.4616805 | Y7: =LN(C7) -> 8.576028 | Z7: =LN(D7) -> 9.282568 | AA7: =LN(E7) -> 8.3116439 | AB7: =LN(F7) -> 7.5873105 | AC7: =LN(G7) -> 7.5490827 | AD7: =LN(H7) -> 10.55114 | AE7: =LN(I7) -> 10.618812 | ... AR7: =LN(V7) -> 5.9889614 | AT7: =X7-X6 -> 0.0089191502 | AU7: =Y7-Y6 -> 0.0079515754 | AV7: =Z7-Z6 -> 0.018497312 | AW7: =AA7-AA6 -> 0.014598799 | AX7: =AB7-AB6 -> 0.0096766734 | AY7: =AC7-AC6 -> 0.013786008 | AZ7: =AD7-AD6 -> 0.0046417182 | BA7: =AE7-AE6 -> 0.010990067 | ... BN7: =AR7-AR6 -> 0.030536724
A8: 1876 | B8: 4772 | C8: 5345 | D8: 10951 | E8: 4128 | F8: 1994 | G8: 1928 | H8: 38398 | I8: 41491 | J8: 28837 | K8: 35713 | L8: 3832 | M8: 434 | N8: 1829 | O8: 4484 | P8: 16545 | Q8: 2930 | R8: 4406 | S8: 2768 | T8: 33200 | U8: 46287 | V8: 411 | X8: =LN(B8) -> 8.4705208 | Y8: =LN(C8) -> 8.5839168 | Z8: =LN(D8) -> 9.3011861 | AA8: =LN(E8) -> 8.3255483 | AB8: =LN(F8) -> 7.597898 | AC8: =LN(G8) -> 7.5642385 | AD8: =LN(H8) -> 10.555761 | AE8: =LN(I8) -> 10.633232 | ... AR8: =LN(V8) -> 6.0185932 | AT8: =X8-X7 -> 0.0088403017 | AU8: =Y8-Y7 -> 0.0078888463 | AV8: =Z8-Z7 -> 0.018618049 | AW8: =AA8-AA7 -> 0.013904359 | AX8: =AB8-AB7 -> 0.010587444 | AY8: =AC8-AC7 -> 0.015155764 | AZ8: =AD8-AD7 -> 0.0046202721 | BA8: =AE8-AE7 -> 0.014419826 | ... BN8: =AR8-AR7 -> 0.029631798
A9: 1877 | B9: 4815 | C9: 5394 | D9: 11156 | E9: 4184 | F9: 2019 | G9: 1957 | H9: 38576 | I9: 42034 | J9: 29067 | K9: 36018 | L9: 3883 | M9: 450 | N9: 1852 | O9: 4511 | P9: 16603 | Q9: 2952 | R9: 4457 | S9: 2786 | T9: 33576 | U9: 47325 | V9: 424 | X9: =LN(B9) -> 8.4794913 | Y9: =LN(C9) -> 8.5930425 | Z9: =LN(D9) -> 9.3197327 | AA9: =LN(E9) -> 8.339023 | AB9: =LN(F9) -> 7.6103576 | AC9: =LN(G9) -> 7.579168 | AD9: =LN(H9) -> 10.560386 | AE9: =LN(I9) -> 10.646234 | ... AR9: =LN(V9) -> 6.0497335 | AT9: =X9-X8 -> 0.008970541 | AU9: =Y9-Y8 -> 0.0091256802 | AV9: =Z9-Z8 -> 0.018546693 | AW9: =AA9-AA8 -> 0.013474699 | AX9: =AB9-AB8 -> 0.012459668 | AY9: =AC9-AC8 -> 0.014929492 | AZ9: =AD9-AD8 -> 0.0046249465 | BA9: =AE9-AE8 -> 0.013002278 | ... BN9: =AR9-AR8 -> 0.031140241
A10: 1878 | B10: 4857 | C10: 5442 | D10: 11365 | E10: 4244 | F10: 2043 | G10: 1983 | H10: 38763 | I10: 42546 | J10: 29252 | K10: 36315 | L10: 3834 | M10: 467 | N10: 1877 | O10: 4538 | P10: 16677 | Q10: 2975 | R10: 4508 | S10: 2803 | T10: 33932 | U10: 48362 | V10: 437 | X10: =LN(B10) -> 8.4881762 | Y10: =LN(C10) -> 8.6019019 | Z10: =LN(D10) -> 9.3382937 | AA10: =LN(E10) -> 8.3532615 | AB10: =LN(F10) -> 7.6221746 | AC10: =LN(G10) -> 7.5923661 | AD10: =LN(H10) -> 10.565221 | AE10: =LN(I10) -> 10.658341 | ... AR10: =LN(V10) -> 6.0799332 | AT10: =X10-X9 -> 0.0086849181 | AU10: =Y10-Y9 -> 0.0088594156 | AV10: =Z10-Z9 -> 0.018560988 | AW10: =AA10-AA9 -> 0.014238494 | AX10: =AB10-AB9 -> 0.011816977 | AY10: =AC10-AC9 -> 0.013198161 | AZ10: =AD10-AD9 -> 0.004835862 | BA10: =AE10-AE9 -> 0.012107029 | ... BN10: =AR10-AR9 -> 0.03019974
A11: 1879 | B11: 4899 | C11: 5492 | D11: 11578 | E11: 4312 | F11: 2064 | G11: 2014 | H11: 38909 | I11: 43052 | J11: 29425 | K11: 36557 | L11: 3986 | M11: 494 | N11: 1902 | O11: 4571 | P11: 16768 | Q11: 2998 | R11: 4555 | S11: 2821 | T11: 34304 | U11: 49400 | V11: 450 | X11: =LN(B11) -> 8.4967864 | Y11: =LN(C11) -> 8.6110478 | Z11: =LN(D11) -> 9.356862 | AA11: =LN(E11) -> 8.3691571 | AB11: =LN(F11) -> 7.6324011 | AC11: =LN(G11) -> 7.6078781 | AD11: =LN(H11) -> 10.568981 | AE11: =LN(I11) -> 10.670164 | ... AR11: =LN(V11) -> 6.1092476 | AT11: =X11-X10 -> 0.0086101393 | AU11: =Y11-Y10 -> 0.0091458475 | AV11: =Z11-Z10 -> 0.018568288 | AW11: =AA11-AA10 -> 0.015895613 | AX11: =AB11-AB10 -> 0.010226532 | AY11: =AC11-AC10 -> 0.015511945 | AZ11: =AD11-AD10 -> 0.0037594029 | BA11: =AE11-AE10 -> 0.011822844 | ... BN11: =AR11-AR10 -> 0.029314388
A12: 1880 | B12: 4941 | C12: 5541 | D12: 11794 | E12: 4384 | F12: 2081 | G12: 2047 | H12: 39045 | I12: 43500 | J12: 29534 | K12: 36807 | L12: 4043 | M12: 520 | N12: 1919 | O12: 4610 | P12: 16859 | Q12: 3021 | R12: 4572 | S12: 2839 | T12: 34623 | U12: 50458 | V12: 464 | X12: =LN(B12) -> 8.505323 | Y12: =LN(C12) -> 8.6199303 | Z12: =LN(D12) -> 9.3753462 | AA12: =LN(E12) -> 8.3857168 | AB12: =LN(F12) -> 7.6406038 | AC12: =LN(G12) -> 7.6241306 | AD12: =LN(H12) -> 10.57247 | AE12: =LN(I12) -> 10.680516 | ... AR12: =LN(V12) -> 6.1398846 | AT12: =X12-X11 -> 0.0085366372 | AU12: =Y12-Y11 -> 0.008882502 | AV12: =Z12-Z11 -> 0.018484182 | AW12: =AA12-AA11 -> 0.016559716 | AX12: =AB12-AB11 -> 0.0082026998 | AY12: =AC12-AC11 -> 0.016252512 | AZ12: =AD12-AD11 -> 0.0034892408 | BA12: =AE12-AE11 -> 0.010352251 | ... BN12: =AR12-AR11 -> 0.030636969
A13: 1881 | B13: 4985 | C13: 5606 | D13: 12015 | E13: 4451 | F13: 2101 | G13: 2072 | H13: 39191 | I13: 43827 | J13: 29672 | K13: 37112 | L13: 4079 | M13: 539 | N13: 1923 | O13: 4651 | P13: 16951 | Q13: 3044 | R13: 4570 | S13: 2853 | T13: 34935 | U13: 51743 | V13: 482 | X13: =LN(B13) -> 8.5141887 | Y13: =LN(C13) -> 8.6315927 | Z13: =LN(D13) -> 9.3939111 | AA13: =LN(E13) -> 8.4008841 | AB13: =LN(F13) -> 7.6501687 | AC13: =LN(G13) -> 7.6362696 | AD13: =LN(H13) -> 10.576202 | AE13: =LN(I13) -> 10.688005 | ... AR13: =LN(V13) -> 6.1779441 | AT13: =X13-X12 -> 0.0088656636 | AU13: =Y13-Y12 -> 0.011662463 | AV13: =Z13-Z12 -> 0.018564942 | AW13: =AA13-AA12 -> 0.01516724 | AX13: =AB13-AB12 -> 0.0095648745 | AY13: =AC13-AC12 -> 0.012139018 | AZ13: =AD13-AD12 -> 0.0037323015 | BA13: =AE13-AE12 -> 0.0074891277 | ... BN13: =AR13-AR12 -> 0.038059562
A14: 1882 | B14: 5030 | C14: 5673 | D14: 12240 | E14: 4503 | F14: 2120 | G14: 2098 | H14: 39337 | I14: 44112 | J14: 29898 | K14: 37414 | L14: 4130 | M14: 555 | N14: 1920 | O14: 4691 | P14: 17043 | Q14: 3073 | R14: 4576 | S14: 2863 | T14: 35206 | U14: 53027 | V14: 502 | X14: =LN(B14) -> 8.5231753 | Y14: =LN(C14) -> 8.6434734 | Z14: =LN(D14) -> 9.4124646 | AA14: =LN(E14) -> 8.4124991 | AB14: =LN(F14) -> 7.6591714 | AC14: =LN(G14) -> 7.6487398 | AD14: =LN(H14) -> 10.579921 | AE14: =LN(I14) -> 10.694487 | ... AR14: =LN(V14) -> 6.2186001 | AT14: =X14-X13 -> 0.0089865807 | AU14: =Y14-Y13 -> 0.011880626 | AV14: =Z14-Z13 -> 0.018553408 | AW14: =AA14-AA13 -> 0.011615051 | AX14: =AB14-AB13 -> 0.0090026668 | AY14: =AC14-AC13 -> 0.012470186 | AZ14: =AD14-AD13 -> 0.0037184232 | BA14: =AE14-AE13 -> 0.0064817885 | ... BN14: =AR14-AR13 -> 0.040656006
... A145: 2013 | B145: 8215 | C145: 10443 | D145: 207432 | E145: 34587 | F145: 5561 | G145: 5269 | H145: 65741 | I145: 82413 | J145: 58156 | K145: 127568 | L145: 16916 | M145: 4374 | N145: 4726 | O145: 10823 | P145: 40658 | Q145: 22054 | R145: 9116 | S145: 7724 | T145: 61789 | U145: 317389 | V145: 3567 | X145: =LN(B145) -> 9.013717 | Y145: =LN(C145) -> 9.2536872 | Z145: =LN(D145) -> 12.242559 | AA145: =LN(E145) -> 10.451233 | AB145: =LN(F145) -> 8.6235332 | AC145: =LN(G145) -> 8.5695959 | AD145: =LN(H145) -> 11.093478 | AE145: =LN(I145) -> 11.319498 | ... AR145: =LN(V145) -> 8.1794802 | AT145: =X145-X144 -> -0.00073010468 | AU145: =Y145-Y144 -> 0.00057471266 | AV145: =Z145-Z144 -> 0.0096544222 | AW145: =AA145-AA144 -> 0.011632434 | AX145: =AB145-AB144 -> 0.0028813274 | AY145: =AC145-AC144 -> 0.0009493972 | AZ145: =AD145-AD144 -> 0.0048947574 | BA145: =AE145-AE144 -> -0.00010920011 | ... BN145: =AR145-AR144 -> 0.0073157332

Sheet  Real GDP Per Capita
A1: Real GDP | B1: Austria | C1: Belgium | D1: Brazil | E1: Canada | F1: Denmark | G1: Finland | H1: France | I1: Germany | J1: Italy | K1: Japan | L1: Netherlands | M1: N. Zealand | N1: Norway | O1: Portugal | P1: Spain | Q1: Sri Lanka | R1: Sweden | S1: Switzerland | T1: UK | U1: USA | V1: Uruguay | X1: Austria | Y1: Belgium | Z1: Brazil | AA1: Canada | AB1: Denmark | AC1: Finland | AD1: France | AE1: Germany | AF1: Italy | AG1: Japan | AH1: Netherlands | AI1: N. Zealand | AJ1: Norway | AK1: Portugal | AL1: Spain | AM1: Sri Lanka | AN1: Sweden | AO1: Switzerland | AP1: UK | AQ1: USA | AR1: Uruguay | AT1: Austria | AU1: Belgium | AV1: Brazil | AW1: Canada | AX1: Denmark | AY1: Finland | AZ1: France | BA1: Germany | BB1: Italy | BC1: Japan | BD1: Netherlands | BE1: N. Zealand | BF1: Norway | BG1: Portugal | BH1: Spain | BI1: Sri Lanka | BJ1: Sweden | BK1: Switzerland | BL1: UK | BM1: USA | BN1: Uruguay
A2: 1870 | B2: 1862.5905 | C2: 2691.5228 | D2: 712.97336 | E2: 1694.5253 | F2: 2003.178 | G2: 1139.6807 | H2: 1875.6507 | I2: 1839.0795 | J2: 1499.3546 | K2: 737.3755 | L2: 2756.7867 | M2: 3099.6564 | N2: 1360.1435 | O2: 975.04044 | P2: 1207.086 | Q2: 851.39986 | R2: 1359.0298 | S2: 2102.0716 | T2: 3190.434 | U2: 2444.6437 | V2: 2180.758 | X2: =LN(B2) -> 7.5297235 | Y2: =LN(C2) -> 7.8978624 | Z2: =LN(D2) -> 6.5694441 | AA2: =LN(E2) -> 7.4351579 | AB2: =LN(F2) -> 7.6024902 | AC2: =LN(G2) -> 7.0385034 | AD2: =LN(H2) -> 7.5367109 | AE2: =LN(I2) -> 7.5170205 | ... AR2: =LN(V2) -> 7.6874278
A3: 1871 | B3: 1979.0958 | C3: 2682.4649 | D3: 716.83367 | E3: 1754.5267 | F3: 1993.0373 | G3: 1126.8393 | H3: 1899.4075 | I3: 1816.5618 | J3: 1506.3357 | K3: 742.00531 | L3: 2734.3234 | M3: 3154.9902 | N3: 1376.0883 | O3: 932.91983 | P3: 1298.0686 | Q3: 826.95035 | R3: 1406.1156 | S3: 2225.3731 | T3: 3331.875 | U3: 2502.8469 | V3: 2177.9661 | X3: =LN(B3) -> 7.5903953 | Y3: =LN(C3) -> 7.8944914 | Z3: =LN(D3) -> 6.5748438 | AA3: =LN(E3) -> 7.4699544 | AB3: =LN(F3) -> 7.597415 | AC3: =LN(G3) -> 7.0271719 | AD3: =LN(H3) -> 7.5492973 | AE3: =LN(I3) -> 7.5047009 | ... AR3: =LN(V3) -> 7.6861467 | AT3: =X3-X2 -> 0.060671816 | AU3: =Y3-Y2 -> -0.0033710196 | AV3: =Z3-Z2 -> 0.0053997742 | AW3: =AA3-AA2 -> 0.034796518 | AX3: =AB3-AB2 -> -0.0050751412 | AY3: =AC3-AC2 -> -0.011331523 | AZ3: =AD3-AD2 -> 0.012586377 | BA3: =AE3-AE2 -> -0.01231956 | ... BN3: =AR3-AR2 -> -0.0012810704
A4: 1872 | B4: 1976.3223 | C4: 2823.647 | D4: 720.6649 | E4: 1705.2 | F4: 2086.9708 | G4: 1145.0324 | H4: 2078.4267 | I4: 1931.3758 | J4: 1475.1322 | K4: 746.00534 | L4: 2770.6171 | M4: 3522.7969 | N4: 1457.3648 | O4: 954.32747 | P4: 1473.1229 | Q4: 784.65869 | R4: 1444.9965 | S4: 2107.5269 | T4: 3319.1654 | U4: 2540.9389 | V4: 2631.8681 | X4: =LN(B4) -> 7.588993 | Y4: =LN(C4) -> 7.9457846 | Z4: =LN(D4) -> 6.5801743 | AA4: =LN(E4) -> 7.4414377 | AB4: =LN(F4) -> 7.6434689 | AC4: =LN(G4) -> 7.0431882 | AD4: =LN(H4) -> 7.6393665 | AE4: =LN(I4) -> 7.5659879 | ... AR4: =LN(V4) -> 7.8754492 | AT4: =X4-X3 -> -0.0014023617 | AU4: =Y4-Y3 -> 0.051293204 | AV4: =Z4-Z3 -> 0.0053304234 | AW4: =AA4-AA3 -> -0.02851673 | AX4: =AB4-AB3 -> 0.046053877 | AY4: =AC4-AC3 -> 0.016016325 | AZ4: =AD4-AD3 -> 0.090069202 | BA4: =AE4-AE3 -> 0.061286971 | ... BN4: =AR4-AR3 -> 0.18930245
A5: 1873 | B5: 1913.0282 | C5: 2820.0584 | D5: 724.46418 | E5: 1841.8788 | F5: 2056.5736 | G5: 1193.3974 | H5: 1922.0961 | I5: 1998.6727 | J5: 1524.4356 | K5: 751.01226 | L5: 2853.406 | M5: 3830.991 | N5: 1481.6111 | O5: 988.19523 | P5: 1597.6057 | Q5: 788.33392 | R5: 1451.0997 | S5: 2152.4862 | T5: 3364.6976 | U5: 2604.2526 | V5: 2601.0638 | X5: =LN(B5) -> 7.5564427 | Y5: =LN(C5) -> 7.9445129 | Z5: =LN(D5) -> 6.5854323 | AA5: =LN(E5) -> 7.5185414 | AB5: =LN(F5) -> 7.6287966 | AC5: =LN(G5) -> 7.0845595 | AD5: =LN(H5) -> 7.5611716 | AE5: =LN(I5) -> 7.6002386 | ... AR5: =LN(V5) -> 7.8636758 | AT5: =X5-X4 -> -0.032550278 | AU5: =Y5-Y4 -> -0.0012716922 | AV5: =Z5-Z4 -> 0.0052580698 | AW5: =AA5-AA4 -> 0.077103717 | AX5: =AB5-AB4 -> -0.01467232 | AY5: =AC5-AC4 -> 0.041371234 | AZ5: =AD5-AD4 -> -0.078194869 | BA5: =AE5-AE4 -> 0.034250705 | ... BN5: =AR5-AR4 -> -0.011773384
A6: 1874 | B6: 1980.9292 | C6: 2889.7719 | D6: 728.39272 | E6: 1853.7159 | F6: 2096.2999 | G6: 1204.1201 | H6: 2157.2325 | I6: 2123.96 | J6: 1513.0827 | K6: 756.17993 | L6: 2727.1028 | M6: 3843.4986 | N6: 1523.7482 | O6: 966.37328 | P6: 1458.8837 | Q6: 774.69671 | R6: 1478.9352 | S6: 2396.6337 | T6: 3386.4441 | U6: 2527.255 | V6: 2315.2455 | X6: =LN(B6) -> 7.5913213 | Y6: =LN(C6) -> 7.9689329 | Z6: =LN(D6) -> 6.5908404 | AA6: =LN(E6) -> 7.5249475 | AB6: =LN(F6) -> 7.6479291 | AC6: =LN(G6) -> 7.0935044 | AD6: =LN(H6) -> 7.6765814 | AE6: =LN(I6) -> 7.6610376 | ... AR6: =LN(V6) -> 7.747271 | AT6: =X6-X5 -> 0.034878588 | AU6: =Y6-Y5 -> 0.024419966 | AV6: =Z6-Z5 -> 0.005408033 | AW6: =AA6-AA5 -> 0.0064060708 | AX6: =AB6-AB5 -> 0.019132519 | AY6: =AC6-AC5 -> 0.0089449177 | AZ6: =AD6-AD5 -> 0.11540981 | BA6: =AE6-AE5 -> 0.060799002 | ... BN6: =AR6-AR5 -> -0.11640481
A7: 1875 | B7: 1973.2554 | C7: 2860.785 | D7: 732.3472 | E7: 1783.9666 | F7: 2111.6016 | G7: 1211.1848 | H7: 2219.0692 | I7: 2112.3517 | J7: 1549.5934 | K7: 809.85439 | L7: 2879.6199 | M7: 3687.8793 | N7: 1551.2199 | O7: 959.39883 | P7: 1496.3304 | Q7: 780.60523 | R7: 1453.0032 | S7: 2645.4545 | T7: 3433.6684 | U7: 2598.5855 | V7: 1942.3559 | X7: =LN(B7) -> 7.5874399 | Y7: =LN(C7) -> 7.9588514 | Z7: =LN(D7) -> 6.5962547 | AA7: =LN(E7) -> 7.4865946 | AB7: =LN(F7) -> 7.655202 | AC7: =LN(G7) -> 7.0993544 | AD7: =LN(H7) -> 7.7048431 | AE7: =LN(I7) -> 7.6555572 | ... AR7: =LN(V7) -> 7.5716569 | AT7: =X7-X6 -> -0.0038813562 | AU7: =Y7-Y6 -> -0.010081502 | AV7: =Z7-Z6 -> 0.005414356 | AW7: =AA7-AA6 -> -0.038352885 | AX7: =AB7-AB6 -> 0.0072728849 | AY7: =AC7-AC6 -> 0.0058499661 | AZ7: =AD7-AD6 -> 0.028261683 | BA7: =AE7-AE6 -> -0.0054804114 | ... BN7: =AR7-AR6 -> -0.17561411
A8: 1876 | B8: 2000.1167 | C8: 2874.6165 | D8: 736.18848 | E8: 1640.9167 | F8: 2130.331 | G8: 1259.2427 | H8: 2028.2195 | I8: 2070.6704 | J8: 1506.0718 | K8: 784.56024 | L8: 2889.8747 | M8: 3623.1152 | N8: 1572.4498 | O8: 931.53434 | P8: 1519.2505 | Q8: 788.7372 | R8: 1539.0377 | S8: 2568.2803 | T8: 3430.1604 | U8: 2570.3545 | V8: 2104.6229 | X8: =LN(B8) -> 7.6009608 | Y8: =LN(C8) -> 7.9636745 | Z8: =LN(D8) -> 6.6014862 | AA8: =LN(E8) -> 7.4030103 | AB8: =LN(F8) -> 7.6640326 | AC8: =LN(G8) -> 7.1382658 | AD8: =LN(H8) -> 7.6149136 | AE8: =LN(I8) -> 7.6356277 | ... AR8: =LN(V8) -> 7.6518916 | AT8: =X8-X7 -> 0.013520878 | AU8: =Y8-Y7 -> 0.0048231893 | AV8: =Z8-Z7 -> 0.0052314556 | AW8: =AA8-AA7 -> -0.083584279 | AX8: =AB8-AB7 -> 0.0088306414 | AY8: =AC8-AC7 -> 0.038911457 | AZ8: =AD8-AD7 -> -0.089929521 | BA8: =AE8-AE7 -> -0.019929481 | ... BN8: =AR8-AR7 -> 0.08023468
A9: 1877 | B9: 2050.4405 | C9: 2884.4841 | D9: 740.13984 | E9: 1727.4407 | F9: 2046.1516 | G9: 1211.2003 | H9: 2127.4822 | I9: 2032.6288 | J9: 1493.4223 | K9: 802.65423 | L9: 2926.6031 | M9: 3982.4667 | N9: 1564.7487 | O9: 969.18643 | P9: 1668.4334 | Q9: 793.02168 | R9: 1505.0482 | S9: 2302.9433 | T9: 3425.197 | U9: 2595.3936 | V9: 2122.6415 | X9: =LN(B9) -> 7.6258099 | Y9: =LN(C9) -> 7.9671013 | Z9: =LN(D9) -> 6.6068391 | AA9: =LN(E9) -> 7.4543962 | AB9: =LN(F9) -> 7.623716 | AC9: =LN(G9) -> 7.0993671 | AD9: =LN(H9) -> 7.6626945 | AE9: =LN(I9) -> 7.6170852 | ... AR9: =LN(V9) -> 7.6604166 | AT9: =X9-X8 -> 0.024849107 | AU9: =Y9-Y8 -> 0.0034267858 | AV9: =Z9-Z8 -> 0.0053529673 | AW9: =AA9-AA8 -> 0.051385936 | AX9: =AB9-AB8 -> -0.040316622 | AY9: =AC9-AC8 -> -0.038898682 | AZ9: =AD9-AD8 -> 0.047780901 | BA9: =AE9-AE8 -> -0.018542459 | ... BN9: =AR9-AR8 -> 0.0085250157
A10: 1878 | B10: 2100.3057 | C10: 2942.2574 | D10: 744.1267 | E10: 1637.2017 | F10: 2102.0852 | G10: 1172.7665 | H10: 2091.1263 | I10: 2102.9983 | J10: 1505.8995 | K10: 793.74914 | L10: 2991.132 | M10: 4270.7602 | N10: 1489.818 | O10: 964.08109 | P10: 1617.9169 | Q10: 717.64706 | R10: 1452.0852 | S10: 2331.4306 | T10: 3402.5006 | U10: 2645.9617 | V10: 2247.1396 | X10: =LN(B10) -> 7.6498382 | Y10: =LN(C10) -> 7.9869324 | Z10: =LN(D10) -> 6.6122113 | AA10: =LN(E10) -> 7.4007438 | AB10: =LN(F10) -> 7.6506851 | AC10: =LN(G10) -> 7.0671208 | AD10: =LN(H10) -> 7.6454581 | AE10: =LN(I10) -> 7.6511193 | ... AR10: =LN(V10) -> 7.7174134 | AT10: =X10-X9 -> 0.024028279 | AU10: =Y10-Y9 -> 0.019831077 | AV10: =Z10-Z9 -> 0.0053721878 | AW10: =AA10-AA9 -> -0.053652463 | AX10: =AB10-AB9 -> 0.026969049 | AY10: =AC10-AC9 -> -0.032246356 | AZ10: =AD10-AD9 -> -0.017236375 | BA10: =AE10-AE9 -> 0.034034127 | ... BN10: =AR10-AR9 -> 0.056996805
A11: 1879 | B11: 2067.9388 | C11: 2944.9199 | D11: 748.14303 | E11: 1765.2338 | F11: 2148.5465 | G11: 1167.4042 | H11: 1953.3068 | I11: 2028.6671 | J11: 1514.3949 | K11: 835.40772 | L11: 2778.2238 | M11: 3569.2409 | N11: 1483.2471 | O11: 959.08991 | P11: 1520.2767 | Q11: 769.51301 | R11: 1522.0637 | S11: 2310.1737 | T11: 3352.5075 | U11: 2909.4332 | V11: 1948.8889 | X11: =LN(B11) -> 7.6343076 | Y11: =LN(C11) -> 7.9878369 | Z11: =LN(D11) -> 6.6175942 | AA11: =LN(E11) -> 7.4760384 | AB11: =LN(F11) -> 7.6725469 | AC11: =LN(G11) -> 7.0625379 | AD11: =LN(H11) -> 7.577279 | AE11: =LN(I11) -> 7.6151343 | ... AR11: =LN(V11) -> 7.5750147 | AT11: =X11-X10 -> -0.015530582 | AU11: =Y11-Y10 -> 0.00090448831 | AV11: =Z11-Z10 -> 0.0053828536 | AW11: =AA11-AA10 -> 0.075294625 | AX11: =AB11-AB10 -> 0.021861783 | AY11: =AC11-AC10 -> -0.0045828742 | AZ11: =AD11-AD10 -> -0.068179096 | BA11: =AE11-AE10 -> -0.035985093 | ... BN11: =AR11-AR10 -> -0.1423987
A12: 1880 | B12: 2078.8379 | C12: 3064.8213 | D12: 752.16212 | E12: 1815.8869 | F12: 2181.4656 | G12: 1154.8266 | H12: 2120.4302 | I12: 1991.4064 | J12: 1580.8786 | K12: 863.39555 | L12: 3045.5108 | M12: 3746.5327 | N12: 1517.2859 | O12: 947.2885 | P12: 1646.0051 | Q12: 830.5197 | R12: 1519.9038 | S12: 2449.8063 | T12: 3477.3199 | U12: 3183.955 | V12: 2081.8966 | X12: =LN(B12) -> 7.6395643 | Y12: =LN(C12) -> 8.0277446 | Z12: =LN(D12) -> 6.6229519 | AA12: =LN(E12) -> 7.5043293 | AB12: =LN(F12) -> 7.6877522 | AC12: =LN(G12) -> 7.0517055 | AD12: =LN(H12) -> 7.6593743 | AE12: =LN(I12) -> 7.5965964 | ... AR12: =LN(V12) -> 7.6410346 | AT12: =X12-X11 -> 0.0052566849 | AU12: =Y12-Y11 -> 0.039907662 | AV12: =Z12-Z11 -> 0.0053577048 | AW12: =AA12-AA11 -> 0.02829085 | AX12: =AB12-AB11 -> 0.015205391 | AY12: =AC12-AC11 -> -0.010832445 | AZ12: =AD12-AD11 -> 0.082095263 | BA12: =AE12-AE11 -> -0.018537835 | ... BN12: =AR12-AR11 -> 0.066019872
A13: 1881 | B13: 2145.1667 | C13: 3069.6761 | D13: 756.22139 | E13: 2039.5776 | F13: 2182.9177 | G13: 1110.0579 | H13: 2193.6402 | I13: 2025.2851 | J13: 1467.4024 | K13: 829.3005 | L13: 3074.2829 | M13: 3764.6215 | N13: 1528.3979 | O13: 970.32896 | P13: 1679.075 | Q13: 886.66229 | R13: 1564.9891 | S13: 2480.8973 | T13: 3568.4268 | U13: 3215.4494 | V13: 1931.5353 | X13: =LN(B13) -> 7.6709725 | Y13: =LN(C13) -> 8.0293273 | Z13: =LN(D13) -> 6.6283342 | AA13: =LN(E13) -> 7.620498 | AB13: =LN(F13) -> 7.6884176 | AC13: =LN(G13) -> 7.0121675 | AD13: =LN(H13) -> 7.6933177 | AE13: =LN(I13) -> 7.6134657 | ... AR13: =LN(V13) -> 7.5660704 | AT13: =X13-X12 -> 0.031408236 | AU13: =Y13-Y12 -> 0.0015827639 | AV13: =Z13-Z12 -> 0.0053822962 | AW13: =AA13-AA12 -> 0.11616876 | AX13: =AB13-AB12 -> 0.0006653938 | AY13: =AC13-AC12 -> -0.039537992 | AZ13: =AD13-AD12 -> 0.033943387 | BA13: =AE13-AE12 -> 0.016869316 | ... BN13: =AR13-AR12 -> -0.074964119
A14: 1882 | B14: 2139.962 | C14: 3136.0568 | D14: 760.29412 | E14: 2109.0722 | F14: 2240.4198 | G14: 1202.8861 | H14: 2288.3455 | I14: 2044.4813 | J14: 1583.8617 | K14: 844.17598 | L14: 3117.4334 | M14: 3645.6757 | N14: 1527.944 | O14: 992.32573 | P14: 1691.6623 | Q14: 935.24243 | R14: 1548.951 | S14: 2399.5809 | T14: 3643.0403 | U14: 3337.9599 | V14: 2079.6813 | X14: =LN(B14) -> 7.6685434 | Y14: =LN(C14) -> 8.0507215 | Z14: =LN(D14) -> 6.6337054 | AA14: =LN(E14) -> 7.6540034 | AB14: =LN(F14) -> 7.7144185 | AC14: =LN(G14) -> 7.092479 | AD14: =LN(H14) -> 7.7355843 | AE14: =LN(I14) -> 7.6228994 | ... AR14: =LN(V14) -> 7.6399699 | AT14: =X14-X13 -> -0.0024291802 | AU14: =Y14-Y13 -> 0.021394163 | AV14: =Z14-Z13 -> 0.0053711782 | AW14: =AA14-AA13 -> 0.033505384 | AX14: =AB14-AB13 -> 0.026000907 | AY14: =AC14-AC13 -> 0.080311548 | AZ14: =AD14-AD13 -> 0.04226669 | BA14: =AE14-AE13 -> 0.0094336668 | ... BN14: =AR14-AR13 -> 0.073899486
... A145: 2013 | B145: 27001.736 | C145: 25531.53 | D145: 5625.7478 | E145: 29004.92 | F145: 23069.955 | G145: 27321.315 | H145: 22835.808 | I145: 24218.992 | J145: 18507.525 | K145: 25408.942 | L145: 24539.2 | M145: 20700.519 | N145: 32361.957 | O145: 14012.174 | P145: 18695.806 | Q145: 5300.4199 | R145: 29596.74 | S145: 28010.974 | T145: 24724.104 | U145: 34633.306 | V145: 11521.629 | X145: =LN(B145) -> 10.203656 | Y145: =LN(C145) -> 10.147669 | Z145: =LN(D145) -> 8.6351092 | AA145: =LN(E145) -> 10.275221 | AB145: =LN(F145) -> 10.046286 | AC145: =LN(G145) -> 10.215422 | AD145: =LN(H145) -> 10.036085 | AE145: =LN(I145) -> 10.094892 | ... AR145: =LN(V145) -> 9.3519813 | AT145: =X145-X144 -> 0.0082770809 | AU145: =Y145-Y144 -> -0.0051623356 | AV145: =Z145-Z144 -> 0.015775293 | AW145: =AA145-AA144 -> 0.011586684 | AX145: =AB145-AB144 -> -0.0089495561 | AY145: =AC145-AC144 -> -0.010827219 | AZ145: =AD145-AD144 -> -0.014619912 | BA145: =AE145-AE144 -> 0.0092487096 | ... BN145: =AR145-AR144 -> 0.022319183
B147: =AVERAGE(B2:B145) -> 7807.9152 | C147: =AVERAGE(C2:C145) -> 8595.2842 | D147: =AVERAGE(D2:D145) -> 2357.9498 | E147: =AVERAGE(E2:E145) -> 9318.6935 | F147: =AVERAGE(F2:F145) -> 9134.3455 | G147: =AVERAGE(G2:G145) -> 7217.4406 | H147: =AVERAGE(H2:H145) -> 8175.4901 | I147: =AVERAGE(I2:I145) -> 7865.1051 | ... V147: =AVERAGE(V2:V145) -> 4498.8661 | X147: =AVERAGE(X2:X145) -> 8.583003 | Y147: =AVERAGE(Y2:Y145) -> 8.7957693 | Z147: =AVERAGE(Z2:Z145) -> 7.4429522 | AA147: =AVERAGE(AA2:AA145) -> 8.7874261 | AB147: =AVERAGE(AB2:AB145) -> 8.7983887 | AC147: =AVERAGE(AC2:AC145) -> 8.3669189 | AD147: =AVERAGE(AD2:AD145) -> 8.6646164 | AE147: =AVERAGE(AE2:AE145) -> 8.6405375 | ... AR147: =AVERAGE(AR2:AR145) -> 8.3023868
B148: =LOG(B147) -> 3.8925351 | C148: =LOG(C147) -> 3.9342602 | D148: =LOG(D147) -> 3.3725346 | E148: =LOG(E147) -> 3.969355 | F148: =LOG(F147) -> 3.9606774 | G148: =LOG(G147) -> 3.8583832 | H148: =LOG(H147) -> 3.9125138 | I148: =LOG(I147) -> 3.8957045 | ... V148: =LOG(V147) -> 3.6531031

Sheet percapital
A1: Real GDP | B1: Austria | C1: Belgium | D1: Brazil | E1: Canada | F1: Denmark | G1: Finland | H1: France | I1: Germany | J1: Italy | K1: Japan | L1: Netherlands | M1: N. Zealand | N1: Norway | O1: Portugal | P1: Spain | Q1: Sri Lanka | R1: Sweden | S1: Switzerland | T1: UK | U1: USA | V1: Uruguay
A2: 1870 | B2: 1862.5905 | C2: 2691.5228 | D2: 712.97336 | E2: 1694.5253 | F2: 2003.178 | G2: 1139.6807 | H2: 1875.6507 | I2: 1839.0795 | J2: 1499.3546 | K2: 737.3755 | L2: 2756.7867 | M2: 3099.6564 | N2: 1360.1435 | O2: 975.04044 | P2: 1207.086 | Q2: 851.39986 | R2: 1359.0298 | S2: 2102.0716 | T2: 3190.434 | U2: 2444.6437 | V2: 2180.758
A3: 1871 | B3: 1979.0958 | C3: 2682.4649 | D3: 716.83367 | E3: 1754.5267 | F3: 1993.0373 | G3: 1126.8393 | H3: 1899.4075 | I3: 1816.5618 | J3: 1506.3357 | K3: 742.00531 | L3: 2734.3234 | M3: 3154.9902 | N3: 1376.0883 | O3: 932.91983 | P3: 1298.0686 | Q3: 826.95035 | R3: 1406.1156 | S3: 2225.3731 | T3: 3331.875 | U3: 2502.8469 | V3: 2177.9661
A4: 1872 | B4: 1976.3223 | C4: 2823.647 | D4: 720.6649 | E4: 1705.2 | F4: 2086.9708 | G4: 1145.0324 | H4: 2078.4267 | I4: 1931.3758 | J4: 1475.1322 | K4: 746.00534 | L4: 2770.6171 | M4: 3522.7969 | N4: 1457.3648 | O4: 954.32747 | P4: 1473.1229 | Q4: 784.65869 | R4: 1444.9965 | S4: 2107.5269 | T4: 3319.1654 | U4: 2540.9389 | V4: 2631.8681
A5: 1873 | B5: 1913.0282 | C5: 2820.0584 | D5: 724.46418 | E5: 1841.8788 | F5: 2056.5736 | G5: 1193.3974 | H5: 1922.0961 | I5: 1998.6727 | J5: 1524.4356 | K5: 751.01226 | L5: 2853.406 | M5: 3830.991 | N5: 1481.6111 | O5: 988.19523 | P5: 1597.6057 | Q5: 788.33392 | R5: 1451.0997 | S5: 2152.4862 | T5: 3364.6976 | U5: 2604.2526 | V5: 2601.0638
A6: 1874 | B6: 1980.9292 | C6: 2889.7719 | D6: 728.39272 | E6: 1853.7159 | F6: 2096.2999 | G6: 1204.1201 | H6: 2157.2325 | I6: 2123.96 | J6: 1513.0827 | K6: 756.17993 | L6: 2727.1028 | M6: 3843.4986 | N6: 1523.7482 | O6: 966.37328 | P6: 1458.8837 | Q6: 774.69671 | R6: 1478.9352 | S6: 2396.6337 | T6: 3386.4441 | U6: 2527.255 | V6: 2315.2455
A7: 1875 | B7: 1973.2554 | C7: 2860.785 | D7: 732.3472 | E7: 1783.9666 | F7: 2111.6016 | G7: 1211.1848 | H7: 2219.0692 | I7: 2112.3517 | J7: 1549.5934 | K7: 809.85439 | L7: 2879.6199 | M7: 3687.8793 | N7: 1551.2199 | O7: 959.39883 | P7: 1496.3304 | Q7: 780.60523 | R7: 1453.0032 | S7: 2645.4545 | T7: 3433.6684 | U7: 2598.5855 | V7: 1942.3559
A8: 1876 | B8: 2000.1167 | C8: 2874.6165 | D8: 736.18848 | E8: 1640.9167 | F8: 2130.331 | G8: 1259.2427 | H8: 2028.2195 | I8: 2070.6704 | J8: 1506.0718 | K8: 784.56024 | L8: 2889.8747 | M8: 3623.1152 | N8: 1572.4498 | O8: 931.53434 | P8: 1519.2505 | Q8: 788.7372 | R8: 1539.0377 | S8: 2568.2803 | T8: 3430.1604 | U8: 2570.3545 | V8: 2104.6229
A9: 1877 | B9: 2050.4405 | C9: 2884.4841 | D9: 740.13984 | E9: 1727.4407 | F9: 2046.1516 | G9: 1211.2003 | H9: 2127.4822 | I9: 2032.6288 | J9: 1493.4223 | K9: 802.65423 | L9: 2926.6031 | M9: 3982.4667 | N9: 1564.7487 | O9: 969.18643 | P9: 1668.4334 | Q9: 793.02168 | R9: 1505.0482 | S9: 2302.9433 | T9: 3425.197 | U9: 2595.3936 | V9: 2122.6415
A10: 1878 | B10: 2100.3057 | C10: 2942.2574 | D10: 744.1267 | E10: 1637.2017 | F10: 2102.0852 | G10: 1172.7665 | H10: 2091.1263 | I10: 2102.9983 | J10: 1505.8995 | K10: 793.74914 | L10: 2991.132 | M10: 4270.7602 | N10: 1489.818 | O10: 964.08109 | P10: 1617.9169 | Q10: 717.64706 | R10: 1452.0852 | S10: 2331.4306 | T10: 3402.5006 | U10: 2645.9617 | V10: 2247.1396
A11: 1879 | B11: 2067.9388 | C11: 2944.9199 | D11: 748.14303 | E11: 1765.2338 | F11: 2148.5465 | G11: 1167.4042 | H11: 1953.3068 | I11: 2028.6671 | J11: 1514.3949 | K11: 835.40772 | L11: 2778.2238 | M11: 3569.2409 | N11: 1483.2471 | O11: 959.08991 | P11: 1520.2767 | Q11: 769.51301 | R11: 1522.0637 | S11: 2310.1737 | T11: 3352.5075 | U11: 2909.4332 | V11: 1948.8889
A12: 1880 | B12: 2078.8379 | C12: 3064.8213 | D12: 752.16212 | E12: 1815.8869 | F12: 2181.4656 | G12: 1154.8266 | H12: 2120.4302 | I12: 1991.4064 | J12: 1580.8786 | K12: 863.39555 | L12: 3045.5108 | M12: 3746.5327 | N12: 1517.2859 | O12: 947.2885 | P12: 1646.0051 | Q12: 830.5197 | R12: 1519.9038 | S12: 2449.8063 | T12: 3477.3199 | U12: 3183.955 | V12: 2081.8966
A13: 1881 | B13: 2145.1667 | C13: 3069.6761 | D13: 756.22139 | E13: 2039.5776 | F13: 2182.9177 | G13: 1110.0579 | H13: 2193.6402 | I13: 2025.2851 | J13: 1467.4024 | K13: 829.3005 | L13: 3074.2829 | M13: 3764.6215 | N13: 1528.3979 | O13: 970.32896 | P13: 1679.075 | Q13: 886.66229 | R13: 1564.9891 | S13: 2480.8973 | T13: 3568.4268 | U13: 3215.4494 | V13: 1931.5353
... A145: 2013 | B145: 27001.736 | C145: 25531.53 | D145: 5625.7478 | E145: 29004.92 | F145: 23069.955 | G145: 27321.315 | H145: 22835.808 | I145: 24218.992 | J145: 18507.525 | K145: 25408.942 | L145: 24539.2 | M145: 20700.519 | N145: 32361.957 | O145: 14012.174 | P145: 18695.806 | Q145: 5300.4199 | R145: 29596.74 | S145: 28010.974 | T145: 24724.104 | U145: 34633.306 | V145: 11521.629

Sheet CO2
A1: CO2 | B1: Austria | C1: Belgium | D1: Brazil | E1: Canada | F1: Denmark | G1: Finland | H1: France | I1: Germany | J1: Italy | K1: Japan | L1: Netherlands | M1: N. Zealand | N1: Norway | O1: Portugal | P1: Spain | Q1: Sri Lanka | R1: Sweden | S1: Switzerland | T1: UK | U1: USA | V1: Uruguay
A2: 1870 | B2: 2010 | C2: 6754 | E2: 334 | F2: 312 | G2: 25 | H2: 13793 | I2: 20917 | J2: 731 | L2: 1349 | N2: 172 | O2: 6 | P2: 839 | R2: 366 | S2: 245 | T2: 62362 | U2: 26916
A3: 1871 | B3: 2768 | C3: 6473 | E3: 486 | F3: 324 | G3: 31 | H3: 13718 | I3: 23294 | J3: 630 | L3: 1359 | N3: 167 | O3: 10 | P3: 802 | R3: 391 | S3: 303 | T3: 66058 | U3: 28117
A4: 1872 | B4: 2731 | C4: 6984 | E4: 504 | F4: 311 | G4: 25 | H4: 16628 | I4: 25139 | J4: 812 | L4: 1455 | N4: 179 | O4: 142 | P4: 890 | R4: 467 | S4: 348 | T4: 69593 | U4: 34472
A5: 1873 | B5: 2928 | C5: 7671 | E5: 439 | F5: 314 | G5: 24 | H5: 17972 | I5: 26847 | J5: 756 | L5: 1403 | N5: 180 | O5: 198 | P5: 856 | R5: 474 | S5: 338 | T5: 72232 | U5: 38075
A6: 1874 | B6: 2498 | C6: 7073 | E6: 443 | F6: 339 | G6: 34 | H6: 17097 | I6: 19540 | J6: 818 | L6: 1294 | N6: 223 | O6: 145 | P6: 851 | R6: 511 | S6: 319 | T6: 70193 | U6: 36653
A7: 1875 | B7: 2145 | C7: 7350 | E7: 512 | F7: 398 | G7: 23 | H7: 17811 | I7: 27707 | J7: 837 | L7: 1479 | N7: 280 | O7: 319 | P7: 898 | R7: 621 | S7: 349 | T7: 74096 | U7: 37049
A8: 1876 | B8: 2208 | C8: 7183 | E8: 507 | F8: 421 | G8: 26 | H8: 17838 | I8: 28231 | J8: 1121 | L8: 1695 | N8: 247 | O8: 313 | P8: 974 | R8: 663 | S8: 408 | T8: 73968 | U8: 36250
A9: 1877 | B9: 1988 | C9: 6837 | E9: 552 | F9: 416 | G9: 31 | H9: 17447 | I9: 27648 | J9: 1038 | L9: 1722 | N9: 333 | O9: 183 | P9: 1032 | R9: 702 | S9: 387 | T9: 75300 | U9: 40168
A10: 1878 | B10: 1976 | C10: 7434 | E10: 528 | F10: 395 | G10: 35 | H10: 17801 | I10: 28533 | J10: 1033 | L10: 1825 | M10: 97 | N10: 297 | O10: 175 | P10: 1025 | R10: 595 | S10: 370 | T10: 73956 | U10: 39275
A11: 1879 | B11: 2419 | C11: 7569 | E11: 596 | F11: 446 | G11: 21 | H11: 18422 | I11: 30253 | J11: 1189 | L11: 1968 | M11: 138 | N11: 312 | O11: 193 | P11: 1084 | R11: 604 | S11: 395 | T11: 74412 | U11: 47890
A12: 1880 | B12: 6454 | C12: 8304 | E12: 1428 | F12: 508 | G12: 27 | H12: 20783 | I12: 33980 | J12: 1383 | L12: 2176 | M12: 179 | N12: 341 | O12: 240 | P12: 1205 | R12: 772 | S12: 456 | T12: 81093 | U12: 54226
A13: 1881 | B13: 2815 | C13: 8360 | E13: 1526 | F13: 538 | G13: 27 | H13: 21284 | I13: 36644 | J13: 1626 | L13: 2191 | M13: 201 | N13: 353 | O13: 243 | P13: 1346 | R13: 751 | S13: 427 | T13: 85238 | U13: 57367
A14: 1882 | B14: 2893 | C14: 8853 | E14: 1806 | F14: 577 | G14: 33 | H14: 22464 | I14: 39210 | J14: 1712 | L14: 2219 | M14: 226 | N14: 386 | O14: 296 | P14: 1469 | R14: 859 | S14: 472 | T14: 85962 | U14: 64245
A15: 1883 | B15: 3210 | C15: 9384 | E15: 2028 | F15: 663 | G15: 32 | H15: 23559 | I15: 41783 | J15: 1814 | L15: 2459 | M15: 253 | N15: 416 | O15: 311 | P15: 1611 | R15: 878 | S15: 522 | T15: 89446 | U15: 69291
A16: 1884 | B16: 3128 | C16: 9244 | E16: 2347 | F16: 660 | G16: 39 | H16: 22629 | I16: 42993 | J16: 2009 | L16: 2461 | M16: 289 | N16: 426 | O16: 328 | P16: 1602 | R16: 969 | S16: 536 | T16: 87090 | U16: 73032
A17: 1885 | B17: 3288 | C17: 9029 | E17: 2250 | F17: 692 | G17: 60 | H17: 21756 | I17: 43991 | J17: 2286 | L17: 2571 | M17: 308 | N17: 487 | O17: 304 | P17: 1572 | R17: 1045 | S17: 558 | T17: 86051 | U17: 74280
A18: 1886 | B18: 3103 | C18: 8762 | E18: 2401 | F18: 663 | G18: 35 | H18: 21581 | I18: 44496 | J18: 2273 | L18: 2625 | M18: 322 | N18: 476 | O18: 336 | P18: 1663 | R18: 1024 | S18: 569 | T18: 85270 | U18: 78456
A19: 1887 | B19: 3345 | C19: 9271 | E19: 2770 | F19: 680 | G19: 35 | H19: 22732 | I19: 46504 | J19: 2770 | L19: 2671 | M19: 338 | N19: 459 | O19: 346 | P19: 1676 | R19: 1038 | S19: 616 | T19: 87457 | U19: 83892
A20: 1888 | B20: 3262 | C20: 9840 | E20: 3633 | F20: 765 | G20: 33 | H20: 23650 | I20: 50859 | J20: 2974 | L20: 2964 | M20: 372 | N20: 531 | O20: 373 | P20: 1756 | R20: 1159 | S20: 629 | T20: 90930 | U20: 102040
A21: 1889 | B21: 3514 | C21: 10053 | E21: 3082 | F21: 817 | G21: 44 | H21: 24235 | I21: 54271 | J21: 3072 | L21: 2896 | M21: 358 | N21: 606 | O21: 429 | P21: 1862 | R21: 1353 | S21: 694 | T21: 94166 | U21: 91578
... A32: 1900 | B32: 7553 | C32: 13555 | E32: 5630 | F32: 1405 | G32: 164 | H32: 35283 | I32: 89181 | J32: 3796 | L32: 3994 | M32: 666 | N32: 1134 | O32: 673 | P32: 3062 | R32: 2503 | S32: 1549 | T32: 114558 | U32: 180878
A33: 1901 | B33: 7741 | C33: 12748 | D33: 574 | E33: 6508 | F33: 1463 | G33: 115 | H33: 34117 | I33: 88853 | J33: 3690 | L33: 3906 | M33: 748 | N33: 1063 | O33: 652 | P33: 3222 | R33: 2326 | S33: 1415 | T33: 112091 | U33: 196923
A34: 1902 | B34: 7002 | C34: 13334 | D34: 684 | E34: 7000 | F34: 1502 | G34: 109 | H34: 32113 | I34: 87115 | J34: 4098 | L34: 3903 | M34: 830 | N34: 1158 | O34: 715 | P34: 3367 | R34: 2436 | S34: 1429 | T34: 116441 | U34: 208650
A35: 1903 | B35: 6973 | C35: 14364 | D35: 666 | E35: 7631 | F35: 1563 | G35: 140 | H35: 35301 | I35: 93777 | J35: 4180 | L35: 4175 | M35: 865 | N35: 1157 | O35: 688 | P35: 3323 | R35: 2676 | S35: 1548 | T35: 117354 | U35: 244106
A36: 1904 | B36: 7349 | C36: 13742 | D36: 715 | E36: 9033 | F36: 1686 | G36: 144 | H36: 34388 | I36: 97195 | J36: 4418 | L36: 4412 | M36: 937 | N36: 1135 | O36: 704 | P36: 3546 | R36: 2818 | S36: 1627 | T36: 117902 | U36: 240235
A37: 1905 | B37: 7671 | C37: 13719 | D37: 764 | E37: 9658 | F37: 1640 | G37: 160 | H37: 34778 | I37: 104346 | J37: 4870 | L37: 4529 | M37: 966 | N37: 1132 | O37: 688 | P37: 3704 | R37: 2774 | S37: 1703 | T37: 119452 | U37: 268695
A38: 1906 | B38: 9153 | C38: 15692 | D38: 875 | E38: 10204 | F38: 1786 | G38: 168 | H38: 37273 | I38: 98782 | J38: 5756 | L38: 4928 | M38: 1054 | N38: 1153 | O38: 791 | P38: 3783 | R38: 3082 | S38: 1882 | T38: 123731 | U38: 282025
A39: 1907 | B39: 11495 | C39: 15918 | D39: 942 | E39: 12825 | F39: 1592 | G39: 242 | H39: 39737 | I39: 120683 | J39: 6225 | L39: 5070 | M39: 1115 | N39: 1305 | O39: 863 | P39: 3847 | R39: 3486 | S39: 2183 | T39: 129249 | U39: 328003
A40: 1908 | B40: 16087 | C40: 15788 | D40: 981 | E40: 12939 | F40: 1975 | G40: 384 | H40: 40042 | I40: 121900 | J40: 6349 | L40: 5164 | M40: 1133 | N40: 1560 | O40: 858 | P40: 4035 | R40: 3724 | S40: 2185 | T40: 126082 | U40: 286838
A41: 1909 | B41: 11509 | C41: 15765 | D41: 985 | E41: 12387 | F41: 2185 | G41: 350 | H41: 40965 | I41: 121608 | J41: 7015 | L41: 5436 | M41: 1164 | N41: 1573 | O41: 872 | P41: 4139 | R41: 3428 | S41: 2202 | T41: 127207 | U41: 317509
A42: 1910 | B42: 15698 | C42: 16727 | D42: 1146 | E42: 14089 | F42: 2006 | G42: 290 | H42: 41106 | I42: 121552 | J42: 7024 | L42: 5686 | M42: 1338 | N42: 1621 | O42: 887 | P42: 4065 | R42: 3545 | S42: 2126 | T42: 128202 | U42: 346405
A43: 1911 | B43: 13111 | C43: 16836 | D43: 1257 | E43: 16449 | F43: 2137 | G43: 359 | H43: 42824 | I43: 125160 | J43: 7243 | L43: 6026 | M43: 1258 | N43: 1659 | O43: 858 | P43: 4020 | R43: 3453 | S43: 2350 | T43: 131373 | U43: 342900
A44: 1912 | B44: 13630 | C44: 17679 | D44: 1526 | E44: 18360 | F44: 2534 | G44: 405 | H44: 43280 | I44: 136223 | J44: 7601 | L44: 6802 | M44: 1327 | N44: 1877 | O44: 997 | P44: 4362 | R44: 3826 | S44: 2391 | T44: 124423 | U44: 366051
... A63: 1931 | B63: 4941 | C63: 22962 | D63: 1138 | E63: 20703 | F63: 3909 | G63: 822 | H63: 59365 | I63: 105239 | J63: 9330 | L63: 12270 | M63: 1157 | N63: 2207 | O63: 1070 | P63: 6151 | R63: 5170 | S63: 2756 | T63: 112510 | U63: 404771
A64: 1932 | B64: 4141 | C64: 18483 | D64: 1138 | E64: 19162 | F64: 3665 | G64: 825 | H64: 52346 | I64: 94792 | J64: 7663 | L64: 11304 | M64: 966 | N64: 2359 | O64: 925 | P64: 5781 | R64: 5114 | S64: 2791 | T64: 108056 | U64: 342904 | V64: 21
A65: 1933 | B65: 3884 | C65: 19832 | D65: 1289 | E65: 18964 | F65: 3650 | G65: 880 | H65: 54423 | I65: 99578 | J65: 8321 | L65: 10527 | M65: 968 | N65: 2505 | O65: 1091 | P65: 5107 | R65: 5327 | S65: 2611 | T65: 107034 | U65: 367681 | V65: 18
A66: 1934 | B66: 3754 | C66: 20460 | D66: 1262 | E66: 21811 | F66: 3997 | G66: 1079 | H66: 54959 | I66: 111530 | J66: 10829 | L66: 10543 | M66: 1087 | N66: 2589 | O66: 1118 | P66: 5527 | R66: 5932 | S66: 2608 | T66: 115509 | U66: 391482 | V66: 14
A67: 1935 | B67: 3800 | C67: 19555 | D67: 1504 | E67: 21506 | F67: 4163 | G67: 960 | H67: 53327 | I67: 123463 | J67: 12389 | L67: 10171 | M67: 1133 | N67: 2670 | O67: 1195 | P67: 6130 | R67: 6241 | S67: 2586 | T67: 117121 | U67: 406731 | V67: 14
A68: 1936 | B68: 3710 | C68: 20473 | D68: 1405 | E68: 23517 | F68: 4307 | G68: 1355 | H68: 54066 | I68: 136376 | J68: 8735 | L68: 10888 | M68: 1140 | N68: 2850 | O68: 1127 | P68: 2199 | R68: 6837 | S68: 2708 | T68: 123860 | U68: 466893 | V68: 15
...

Sheet CO2 per capita
A1: CO2 per capita | B1: Austria | C1: Belgium | D1: Brazil | E1: Canada | F1: Denmark | G1: Finland | H1: France | I1: Germany | J1: Italy | K1: Japan | L1: Netherlands | M1: N. Zealand | N1: Norway | O1: Portugal | P1: Spain | Q1: Sri Lanka | R1: Sweden | S1: Switzerland | T1: UK | U1: USA | V1: Uruguay
A2: 1870 | B2: =('CO2'!B2/Population!B2)*1000 -> 444.69027 | C2: =('CO2'!C2/Population!C2)*1000 -> 1325.3532 | D2: =('CO2'!D2/Population!D2)*1000 -> 0 | E2: =('CO2'!E2/Population!E2)*1000 -> 88.336419 | F2: =('CO2'!F2/Population!F2)*1000 -> 165.25424 | G2: =('CO2'!G2/Population!G2)*1000 -> 14.253136 | H2: =('CO2'!H2/Population!H2)*1000 -> 358.81894 | I2: =('CO2'!I2/Population!I2)*1000 -> 533.1753 | ... V2: =('CO2'!V2/Population!V2)*1000 -> 0
A3: 1871 | B3: =('CO2'!B3/Population!B3)*1000 -> 606.75142 | C3: =('CO2'!C3/Population!C3)*1000 -> 1260.074 | D3: =('CO2'!D3/Population!D3)*1000 -> 0 | E3: =('CO2'!E3/Population!E3)*1000 -> 127.86109 | F3: =('CO2'!F3/Population!F3)*1000 -> 170.25749 | G3: =('CO2'!G3/Population!G3)*1000 -> 17.357223 | H3: =('CO2'!H3/Population!H3)*1000 -> 363.57372 | I3: =('CO2'!I3/Population!I3)*1000 -> 590.37916 | ... V3: =('CO2'!V3/Population!V3)*1000 -> 0
A4: 1872 | B4: =('CO2'!B4/Population!B4)*1000 -> 593.17984 | C4: =('CO2'!C4/Population!C4)*1000 -> 1348.7833 | D4: =('CO2'!D4/Population!D4)*1000 -> 0 | E4: =('CO2'!E4/Population!E4)*1000 -> 130.23256 | F4: =('CO2'!F4/Population!F4)*1000 -> 162.14807 | G4: =('CO2'!G4/Population!G4)*1000 -> 13.743815 | H4: =('CO2'!H4/Population!H4)*1000 -> 441.30683 | I4: =('CO2'!I4/Population!I4)*1000 -> 633.36777 | ... V4: =('CO2'!V4/Population!V4)*1000 -> 0
A5: 1873 | B5: =('CO2'!B5/Population!B5)*1000 -> 630.21954 | C5: =('CO2'!C5/Population!C5)*1000 -> 1469.8218 | D5: =('CO2'!D5/Population!D5)*1000 -> 0 | E5: =('CO2'!E5/Population!E5)*1000 -> 111.33655 | F5: =('CO2'!F5/Population!F5)*1000 -> 162.2739 | G5: =('CO2'!G5/Population!G5)*1000 -> 12.994044 | H5: =('CO2'!H5/Population!H5)*1000 -> 474.35796 | I5: =('CO2'!I5/Population!I5)*1000 -> 670.88987 | ... V5: =('CO2'!V5/Population!V5)*1000 -> 0
A6: 1874 | B6: =('CO2'!B6/Population!B6)*1000 -> 532.84983 | C6: =('CO2'!C6/Population!C6)*1000 -> 1344.4212 | D6: =('CO2'!D6/Population!D6)*1000 -> 0 | E6: =('CO2'!E6/Population!E6)*1000 -> 110.41874 | F6: =('CO2'!F6/Population!F6)*1000 -> 173.49028 | G6: =('CO2'!G6/Population!G6)*1000 -> 18.152696 | H6: =('CO2'!H6/Population!H6)*1000 -> 449.40069 | I6: =('CO2'!I6/Population!I6)*1000 -> 483.06551 | ... V6: =('CO2'!V6/Population!V6)*1000 -> 0
A7: 1875 | B7: =('CO2'!B7/Population!B7)*1000 -> 453.48837 | C7: =('CO2'!C7/Population!C7)*1000 -> 1386.0079 | D7: =('CO2'!D7/Population!D7)*1000 -> 0 | E7: =('CO2'!E7/Population!E7)*1000 -> 125.76762 | F7: =('CO2'!F7/Population!F7)*1000 -> 201.72326 | G7: =('CO2'!G7/Population!G7)*1000 -> 12.111638 | H7: =('CO2'!H7/Population!H7)*1000 -> 466.00037 | I7: =('CO2'!I7/Population!I7)*1000 -> 677.48246 | ... V7: =('CO2'!V7/Population!V7)*1000 -> 0
A8: 1876 | B8: =('CO2'!B8/Population!B8)*1000 -> 462.69908 | C8: =('CO2'!C8/Population!C8)*1000 -> 1343.8728 | D8: =('CO2'!D8/Population!D8)*1000 -> 0 | E8: =('CO2'!E8/Population!E8)*1000 -> 122.81977 | F8: =('CO2'!F8/Population!F8)*1000 -> 211.1334 | G8: =('CO2'!G8/Population!G8)*1000 -> 13.485477 | H8: =('CO2'!H8/Population!H8)*1000 -> 464.55545 | I8: =('CO2'!I8/Population!I8)*1000 -> 680.41262 | ... V8: =('CO2'!V8/Population!V8)*1000 -> 0
A9: 1877 | B9: =('CO2'!B9/Population!B9)*1000 -> 412.87643 | C9: =('CO2'!C9/Population!C9)*1000 -> 1267.5195 | D9: =('CO2'!D9/Population!D9)*1000 -> 0 | E9: =('CO2'!E9/Population!E9)*1000 -> 131.93117 | F9: =('CO2'!F9/Population!F9)*1000 -> 206.0426 | G9: =('CO2'!G9/Population!G9)*1000 -> 15.840572 | H9: =('CO2'!H9/Population!H9)*1000 -> 452.27603 | I9: =('CO2'!I9/Population!I9)*1000 -> 657.75325 | ... V9: =('CO2'!V9/Population!V9)*1000 -> 0
A10: 1878 | B10: =('CO2'!B10/Population!B10)*1000 -> 406.8355 | C10: =('CO2'!C10/Population!C10)*1000 -> 1366.0419 | D10: =('CO2'!D10/Population!D10)*1000 -> 0 | E10: =('CO2'!E10/Population!E10)*1000 -> 124.41093 | F10: =('CO2'!F10/Population!F10)*1000 -> 193.34312 | G10: =('CO2'!G10/Population!G10)*1000 -> 17.650025 | H10: =('CO2'!H10/Population!H10)*1000 -> 459.22658 | I10: =('CO2'!I10/Population!I10)*1000 -> 670.63884 | ... V10: =('CO2'!V10/Population!V10)*1000 -> 0
A11: 1879 | B11: =('CO2'!B11/Population!B11)*1000 -> 493.77424 | C11: =('CO2'!C11/Population!C11)*1000 -> 1378.1865 | D11: =('CO2'!D11/Population!D11)*1000 -> 0 | E11: =('CO2'!E11/Population!E11)*1000 -> 138.21892 | F11: =('CO2'!F11/Population!F11)*1000 -> 216.08527 | G11: =('CO2'!G11/Population!G11)*1000 -> 10.427011 | H11: =('CO2'!H11/Population!H11)*1000 -> 473.46372 | I11: =('CO2'!I11/Population!I11)*1000 -> 702.70835 | ... V11: =('CO2'!V11/Population!V11)*1000 -> 0
A12: 1880 | B12: =('CO2'!B12/Population!B12)*1000 -> 1306.2133 | C12: =('CO2'!C12/Population!C12)*1000 -> 1498.6465 | D12: =('CO2'!D12/Population!D12)*1000 -> 0 | E12: =('CO2'!E12/Population!E12)*1000 -> 325.72993 | F12: =('CO2'!F12/Population!F12)*1000 -> 244.11341 | G12: =('CO2'!G12/Population!G12)*1000 -> 13.190034 | H12: =('CO2'!H12/Population!H12)*1000 -> 532.28326 | I12: =('CO2'!I12/Population!I12)*1000 -> 781.14943 | ... V12: =('CO2'!V12/Population!V12)*1000 -> 0
A13: 1881 | B13: =('CO2'!B13/Population!B13)*1000 -> 564.69408 | C13: =('CO2'!C13/Population!C13)*1000 -> 1491.2594 | D13: =('CO2'!D13/Population!D13)*1000 -> 0 | E13: =('CO2'!E13/Population!E13)*1000 -> 342.8443 | F13: =('CO2'!F13/Population!F13)*1000 -> 256.06854 | G13: =('CO2'!G13/Population!G13)*1000 -> 13.030888 | H13: =('CO2'!H13/Population!H13)*1000 -> 543.08387 | I13: =('CO2'!I13/Population!I13)*1000 -> 836.1056 | ... V13: =('CO2'!V13/Population!V13)*1000 -> 0
... A142: 2010 | B142: =('CO2'!B142/Population!B142)*1000 -> 2221.2346 | C142: =('CO2'!C142/Population!C142)*1000 -> 2850.4269 | D142: =('CO2'!D142/Population!D142)*1000 -> 569.09898 | E142: =('CO2'!E142/Population!E142)*1000 -> 4044.2107 | F142: =('CO2'!F142/Population!F142)*1000 -> 2288.7439 | G142: =('CO2'!G142/Population!G142)*1000 -> 3209.9353 | H142: =('CO2'!H142/Population!H142)*1000 -> 1521.3095 | I142: =('CO2'!I142/Population!I142)*1000 -> 2467.4436 | ... V142: =('CO2'!V142/Population!V142)*1000 -> 516.68092
